## 1.Error 实例对象
Js解析或运行时，一旦发生错误，引擎就会抛出一个错误对象。Js原生提供Error构造函数，所有抛出的错误都是这个构造函数的实例。
+ Error构造函数接受一个参数，表示错误提示。
+ message：错误提示信息。
+ 非标准属性
  + name：错误名称
  + stack：错误发生时的堆栈
抛出Error实例对象以后，整个程序就中断。大多数 JavaScript 引擎，name和stack属性，分别表示错误的名称和错误的堆栈，但不是每种实现都有。
```
function throwit() {
  throw new Error('');
}

function catchit() {
  try {
    throwit();
  } catch(e) {
    console.log(e.stack); // print stack trace
  }
}

catchit()
// Error
//    at throwit (~/examples/throwcatch.js:9:11)
//    at catchit (~/examples/throwcatch.js:3:9)
//    at repl:1:5
```
上面代码中，错误堆栈的最内层是throwit函数，然后是catchit函数，最后是函数的运行环境。

## 2.原生错误类型
Error实例对象是最一般的错误类型，在它的基础上，JavaScript 还定义了其他6种错误对象。也就是说，存在Error的6个派生对象。
+ 1.SyntaxError 对象
  + SyntaxError对象是解析代码时发生的语法错误,可以语法解析阶段就可以发现。
+ 2.ReferenceError 对象
  + ReferenceError对象是引用一个不存在的变量时发生的错误，另一种触发场景是，将一个值分配给无法分配的对象，比如对函数的运行结果赋值。
+ 3.RangeError 对象
  + RangeError对象是一个值超出有效范围时发生的错误。主要有几种情况，一是数组长度为负数，二是Number对象的方法参数超出范围，以及函数堆栈超过最大值。
+ 4.TypeError 对象
  + TypeError对象是变量或参数不是预期类型时发生的错误。
```
var obj = {};
obj.unknownMethod()
// Uncaught TypeError: obj.unknownMethod is not a function
```
+ 5.URIError 对象
  + URIError对象是 URI 相关函数的参数不正确时抛出的错误，主要涉及encodeURI()、decodeURI()、encodeURIComponent()、decodeURIComponent()、escape()和unescape()这六个函数。
+ 6.EvalError 对象
+ eval函数没有被正确执行时，会抛出EvalError错误。该错误类型已经不再使用了，只是为了保证与以前代码兼容，才继续保留。
+ 自定义错误对象
```
function UserError(message) {
  this.message = message || '默认信息';
  this.name = 'UserError';
}

UserError.prototype = new Error();
UserError.prototype.constructor = UserError;
```
## 3.throw 语句
+ throw语句的作用是手动中断程序执行，抛出一个错误,也可以抛出自定义错误。
+ 实际上，throw可以抛出任何类型的值。也就是说，它的参数可以是任何值。
+ 对于 JavaScript 引擎来说，遇到throw语句，程序就中止了。引擎会接收到throw抛出的信息，可能是一个错误实例，也可能是其他类型的值。
## 4.try...catch 结构
一旦发生错误，程序就中止执行了。JavaScript 提供了try...catch结构，允许对错误进行处理，选择是否往下执行。
## 5.finally 代码块
try...catch结构允许在最后添加一个finally代码块，表示不管是否出现错误，都必需在最后运行的语句。中断执行之前，会先执行finally代码块。
+ 下面的例子充分反映了try...catch...finally这三者之间的执行顺序。
```
function f() {
  try {
    console.log(0);
    throw 'bug';
  } catch(e) {
    console.log(1);
    return true; // 这句原本会延迟到 finally 代码块结束再执行
    console.log(2); // 不会运行
  } finally {
    console.log(3);
    return false; // 这句会覆盖掉前面那句 return
    console.log(4); // 不会运行
  }

  console.log(5); // 不会运行
}

var result = f();
// 0
// 1
// 3

result
// false
```
上面代码中，catch代码块结束执行之前，会先执行finally代码块。




